testOrders.txt
101,N,A001,S,3000,6.8
101,N,A002,S,1000,6.9
101,N,A003,B,2000,6.7
101,N,A004,B,1000,6.8
101,A,A003,B,2000,6.9
102,N,A005,S,2000,10.2
102,N,A006,B,2000,10.1
102,N,A007,B,2000,10.1
102,C,A006,B,2000,10.1
